<?xml version="1.0" encoding="utf-8"?>
<!-- This URDF was automatically created by SolidWorks to URDF Exporter! Originally created by Stephen Brawner (brawner@gmail.com) 
     Commit Version: 1.5.1-0-g916b5db  Build Version: 1.5.7152.31018
     For more information, please see http://wiki.ros.org/sw_urdf_exporter -->
<robot
  name="cylinder_joint_25asm_13">
  <link
    name="link0">
    <inertial>
      <origin
        xyz="-2.21907652596446E-08 -1.16344392510809E-08 0.000538247791607803"
        rpy="0 0 0" />
      <mass
        value="7.14380964147276E-06" />
      <inertia
        ixx="7.09547840102883E-12"
        ixy="4.28536440220919E-17"
        ixz="7.27330777188676E-17"
        iyy="8.71236658742558E-12"
        iyz="1.14893231592751E-16"
        izz="1.39367891333543E-11" />
    </inertial>
    <visual>
      <origin
        xyz="0 0 0"
        rpy="0 0 0" />
      <geometry>
        <mesh
          filename="package://cylinder_joint_25asm_13/meshes/link0.STL" />
      </geometry>
      <material
        name="">
        <color
          rgba="0.647058823529412 0.619607843137255 0.588235294117647 1" />
      </material>
    </visual>
    <collision>
      <origin
        xyz="0 0 0"
        rpy="0 0 0" />
      <geometry>
        <mesh
          filename="package://cylinder_joint_25asm_13/meshes/link0.STL" />
      </geometry>
    </collision>
  </link>
  <link
    name="link1">
    <inertial>
      <origin
        xyz="2.21907652597405E-08 0.000838247791607803 -1.16344392510295E-08"
        rpy="0 0 0" />
      <mass
        value="7.14380964147277E-06" />
      <inertia
        ixx="7.09547840102883E-12"
        ixy="-7.27330777189981E-17"
        ixz="-4.28536440221508E-17"
        iyy="1.39367891333544E-11"
        iyz="1.14893231591823E-16"
        izz="8.71236658742558E-12" />
    </inertial>
    <visual>
      <origin
        xyz="0 0 0"
        rpy="0 0 0" />
      <geometry>
        <mesh
          filename="package://cylinder_joint_25asm_13/meshes/link1.STL" />
      </geometry>
      <material
        name="">
        <color
          rgba="0.647058823529412 0.619607843137255 0.588235294117647 1" />
      </material>
    </visual>
    <collision>
      <origin
        xyz="0 0 0"
        rpy="0 0 0" />
      <geometry>
        <mesh
          filename="package://cylinder_joint_25asm_13/meshes/link1.STL" />
      </geometry>
    </collision>
  </link>
  <joint
    name="joint1"
    type="continuous">
    <origin
      xyz="0 0 0.0007"
      rpy="1.5708 0 1.5708" />
    <parent
      link="link0" />
    <child
      link="link1" />
    <axis
      xyz="0 0 1" />
    <limit
      lower="-0.157"
      upper="0.157"
      effort="100"
      velocity="1" />
  </joint>
  <link
    name="link2">
    <inertial>
      <origin
        xyz="-2.21907652596427E-08 0.000838247791607803 1.16344392512799E-08"
        rpy="0 0 0" />
      <mass
        value="7.14380964147276E-06" />
      <inertia
        ixx="7.09547840102883E-12"
        ixy="7.2733077718779E-17"
        ixz="-4.28536440221158E-17"
        iyy="1.39367891333544E-11"
        iyz="-1.14893231591539E-16"
        izz="8.71236658742558E-12" />
    </inertial>
    <visual>
      <origin
        xyz="0 0 0"
        rpy="0 0 0" />
      <geometry>
        <mesh
          filename="package://cylinder_joint_25asm_13/meshes/link2.STL" />
      </geometry>
      <material
        name="">
        <color
          rgba="0.647058823529412 0.619607843137255 0.588235294117647 1" />
      </material>
    </visual>
    <collision>
      <origin
        xyz="0 0 0"
        rpy="0 0 0" />
      <geometry>
        <mesh
          filename="package://cylinder_joint_25asm_13/meshes/link2.STL" />
      </geometry>
    </collision>
  </link>
  <joint
    name="joint2"
    type="continuous">
    <origin
      xyz="0 0.001 0"
      rpy="0 1.5708 0" />
    <parent
      link="link1" />
    <child
      link="link2" />
    <axis
      xyz="0 0 1" />
    <limit
      lower="-0.157"
      upper="0.157"
      effort="100"
      velocity="1" />
  </joint>
  <link
    name="link3">
    <inertial>
      <origin
        xyz="-2.21907652596674E-08 0.000838247791607803 1.16344392514508E-08"
        rpy="0 0 0" />
      <mass
        value="7.14380964147276E-06" />
      <inertia
        ixx="7.09547840102883E-12"
        ixy="7.27330777185047E-17"
        ixz="-4.28536440225979E-17"
        iyy="1.39367891333543E-11"
        iyz="-1.14893231591706E-16"
        izz="8.71236658742558E-12" />
    </inertial>
    <visual>
      <origin
        xyz="0 0 0"
        rpy="0 0 0" />
      <geometry>
        <mesh
          filename="package://cylinder_joint_25asm_13/meshes/link3.STL" />
      </geometry>
      <material
        name="">
        <color
          rgba="0.647058823529412 0.619607843137255 0.588235294117647 1" />
      </material>
    </visual>
    <collision>
      <origin
        xyz="0 0 0"
        rpy="0 0 0" />
      <geometry>
        <mesh
          filename="package://cylinder_joint_25asm_13/meshes/link3.STL" />
      </geometry>
    </collision>
  </link>
  <joint
    name="joint3"
    type="continuous">
    <origin
      xyz="0 0.001 0"
      rpy="3.1416 -1.5708 0" />
    <parent
      link="link2" />
    <child
      link="link3" />
    <axis
      xyz="0 0 1" />
    <limit
      lower="-0.157"
      upper="0.157"
      effort="100"
      velocity="1" />
  </joint>
  <link
    name="link4">
    <inertial>
      <origin
        xyz="-2.21907652595925E-08 0.000838247791607803 1.16344392505559E-08"
        rpy="0 0 0" />
      <mass
        value="7.14380964147276E-06" />
      <inertia
        ixx="7.09547840102882E-12"
        ixy="7.27330777185742E-17"
        ixz="-4.28536440226602E-17"
        iyy="1.39367891333543E-11"
        iyz="-1.14893231591943E-16"
        izz="8.71236658742557E-12" />
    </inertial>
    <visual>
      <origin
        xyz="0 0 0"
        rpy="0 0 0" />
      <geometry>
        <mesh
          filename="package://cylinder_joint_25asm_13/meshes/link4.STL" />
      </geometry>
      <material
        name="">
        <color
          rgba="0.647058823529412 0.619607843137255 0.588235294117647 1" />
      </material>
    </visual>
    <collision>
      <origin
        xyz="0 0 0"
        rpy="0 0 0" />
      <geometry>
        <mesh
          filename="package://cylinder_joint_25asm_13/meshes/link4.STL" />
      </geometry>
    </collision>
  </link>
  <joint
    name="joint4"
    type="continuous">
    <origin
      xyz="0 0.001 0"
      rpy="0 1.5708 0" />
    <parent
      link="link3" />
    <child
      link="link4" />
    <axis
      xyz="0 0 1" />
    <limit
      lower="-0.157"
      upper="0.157"
      effort="100"
      velocity="1" />
  </joint>
  <link
    name="link5">
    <inertial>
      <origin
        xyz="-2.21907652597814E-08 0.000838247791607805 1.16344392510284E-08"
        rpy="0 0 0" />
      <mass
        value="7.14380964147276E-06" />
      <inertia
        ixx="7.09547840102882E-12"
        ixy="7.27330777185579E-17"
        ixz="-4.28536440225277E-17"
        iyy="1.39367891333543E-11"
        iyz="-1.1489323159178E-16"
        izz="8.71236658742557E-12" />
    </inertial>
    <visual>
      <origin
        xyz="0 0 0"
        rpy="0 0 0" />
      <geometry>
        <mesh
          filename="package://cylinder_joint_25asm_13/meshes/link5.STL" />
      </geometry>
      <material
        name="">
        <color
          rgba="0.647058823529412 0.619607843137255 0.588235294117647 1" />
      </material>
    </visual>
    <collision>
      <origin
        xyz="0 0 0"
        rpy="0 0 0" />
      <geometry>
        <mesh
          filename="package://cylinder_joint_25asm_13/meshes/link5.STL" />
      </geometry>
    </collision>
  </link>
  <joint
    name="joint5"
    type="continuous">
    <origin
      xyz="0 0.001 0"
      rpy="3.1416 -1.5708 0" />
    <parent
      link="link4" />
    <child
      link="link5" />
    <axis
      xyz="0 0 1" />
    <limit
      lower="-0.157"
      upper="0.157"
      effort="100"
      velocity="1" />
  </joint>
  <link
    name="link6">
    <inertial>
      <origin
        xyz="-2.21907652596203E-08 0.000838247791607804 1.16344392499469E-08"
        rpy="0 0 0" />
      <mass
        value="7.14380964147276E-06" />
      <inertia
        ixx="7.09547840102882E-12"
        ixy="7.27330777187836E-17"
        ixz="-4.28536440227107E-17"
        iyy="1.39367891333543E-11"
        iyz="-1.14893231591542E-16"
        izz="8.71236658742557E-12" />
    </inertial>
    <visual>
      <origin
        xyz="0 0 0"
        rpy="0 0 0" />
      <geometry>
        <mesh
          filename="package://cylinder_joint_25asm_13/meshes/link6.STL" />
      </geometry>
      <material
        name="">
        <color
          rgba="0.647058823529412 0.619607843137255 0.588235294117647 1" />
      </material>
    </visual>
    <collision>
      <origin
        xyz="0 0 0"
        rpy="0 0 0" />
      <geometry>
        <mesh
          filename="package://cylinder_joint_25asm_13/meshes/link6.STL" />
      </geometry>
    </collision>
  </link>
  <joint
    name="joint6"
    type="continuous">
    <origin
      xyz="0 0.001 0"
      rpy="0 1.5708 0" />
    <parent
      link="link5" />
    <child
      link="link6" />
    <axis
      xyz="0 0 1" />
    <limit
      lower="-0.157"
      upper="0.157"
      effort="100"
      velocity="1" />
  </joint>
  <link
    name="link7">
    <inertial>
      <origin
        xyz="-2.21907652597862E-08 0.000838247791607803 1.16344392505934E-08"
        rpy="0 0 0" />
      <mass
        value="7.14380964147276E-06" />
      <inertia
        ixx="7.09547840102882E-12"
        ixy="7.27330777190427E-17"
        ixz="-4.28536440224905E-17"
        iyy="1.39367891333543E-11"
        iyz="-1.14893231592436E-16"
        izz="8.71236658742558E-12" />
    </inertial>
    <visual>
      <origin
        xyz="0 0 0"
        rpy="0 0 0" />
      <geometry>
        <mesh
          filename="package://cylinder_joint_25asm_13/meshes/link7.STL" />
      </geometry>
      <material
        name="">
        <color
          rgba="0.647058823529412 0.619607843137255 0.588235294117647 1" />
      </material>
    </visual>
    <collision>
      <origin
        xyz="0 0 0"
        rpy="0 0 0" />
      <geometry>
        <mesh
          filename="package://cylinder_joint_25asm_13/meshes/link7.STL" />
      </geometry>
    </collision>
  </link>
  <joint
    name="joint7"
    type="continuous">
    <origin
      xyz="0 0.001 0"
      rpy="3.1416 -1.5708 0" />
    <parent
      link="link6" />
    <child
      link="link7" />
    <axis
      xyz="0 0 1" />
    <limit
      lower="-0.157"
      upper="0.157"
      effort="100"
      velocity="1" />
  </joint>
  <link
    name="link8">
    <inertial>
      <origin
        xyz="-2.21907652596475E-08 0.000838247791607803 1.16344392498305E-08"
        rpy="0 0 0" />
      <mass
        value="7.14380964147276E-06" />
      <inertia
        ixx="7.09547840102882E-12"
        ixy="7.27330777186182E-17"
        ixz="-4.2853644021828E-17"
        iyy="1.39367891333543E-11"
        iyz="-1.14893231592717E-16"
        izz="8.71236658742557E-12" />
    </inertial>
    <visual>
      <origin
        xyz="0 0 0"
        rpy="0 0 0" />
      <geometry>
        <mesh
          filename="package://cylinder_joint_25asm_13/meshes/link8.STL" />
      </geometry>
      <material
        name="">
        <color
          rgba="0.647058823529412 0.619607843137255 0.588235294117647 1" />
      </material>
    </visual>
    <collision>
      <origin
        xyz="0 0 0"
        rpy="0 0 0" />
      <geometry>
        <mesh
          filename="package://cylinder_joint_25asm_13/meshes/link8.STL" />
      </geometry>
    </collision>
  </link>
  <joint
    name="joint8"
    type="continuous">
    <origin
      xyz="0 0.001 0"
      rpy="0 1.5708 0" />
    <parent
      link="link7" />
    <child
      link="link8" />
    <axis
      xyz="0 0 1" />
    <limit
      lower="-0.157"
      upper="0.157"
      effort="100"
      velocity="1" />
  </joint>
  <link
    name="link9">
    <inertial>
      <origin
        xyz="-2.21907652596476E-08 0.000838247791607802 1.1634439250027E-08"
        rpy="0 0 0" />
      <mass
        value="7.14380964147276E-06" />
      <inertia
        ixx="7.09547840102882E-12"
        ixy="7.27330777186689E-17"
        ixz="-4.28536440227988E-17"
        iyy="1.39367891333543E-11"
        iyz="-1.14893231592105E-16"
        izz="8.71236658742557E-12" />
    </inertial>
    <visual>
      <origin
        xyz="0 0 0"
        rpy="0 0 0" />
      <geometry>
        <mesh
          filename="package://cylinder_joint_25asm_13/meshes/link9.STL" />
      </geometry>
      <material
        name="">
        <color
          rgba="0.647058823529412 0.619607843137255 0.588235294117647 1" />
      </material>
    </visual>
    <collision>
      <origin
        xyz="0 0 0"
        rpy="0 0 0" />
      <geometry>
        <mesh
          filename="package://cylinder_joint_25asm_13/meshes/link9.STL" />
      </geometry>
    </collision>
  </link>
  <joint
    name="joint9"
    type="continuous">
    <origin
      xyz="0 0.001 0"
      rpy="3.1416 -1.5708 0" />
    <parent
      link="link8" />
    <child
      link="link9" />
    <axis
      xyz="0 0 1" />
    <limit
      lower="-0.157"
      upper="0.157"
      effort="100"
      velocity="1" />
  </joint>
  <link
    name="link10">
    <inertial>
      <origin
        xyz="2.21907652594878E-08 0.0008382477916078 -1.16344392530908E-08"
        rpy="0 0 0" />
      <mass
        value="7.14380964147275E-06" />
      <inertia
        ixx="7.09547840102882E-12"
        ixy="-7.27330777184099E-17"
        ixz="-4.28536440220448E-17"
        iyy="1.39367891333543E-11"
        iyz="1.14893231592422E-16"
        izz="8.71236658742557E-12" />
    </inertial>
    <visual>
      <origin
        xyz="0 0 0"
        rpy="0 0 0" />
      <geometry>
        <mesh
          filename="package://cylinder_joint_25asm_13/meshes/link10.STL" />
      </geometry>
      <material
        name="">
        <color
          rgba="0.647058823529412 0.619607843137255 0.588235294117647 1" />
      </material>
    </visual>
    <collision>
      <origin
        xyz="0 0 0"
        rpy="0 0 0" />
      <geometry>
        <mesh
          filename="package://cylinder_joint_25asm_13/meshes/link10.STL" />
      </geometry>
    </collision>
  </link>
  <joint
    name="joint10"
    type="continuous">
    <origin
      xyz="0 0.001 0"
      rpy="0 1.5708 0" />
    <parent
      link="link9" />
    <child
      link="link10" />
    <axis
      xyz="0 0 1" />
    <limit
      lower="-0.157"
      upper="0.157"
      effort="100"
      velocity="1" />
  </joint>
  <link
    name="link11">
    <inertial>
      <origin
        xyz="2.21907652597516E-08 0.000838247791607806 -1.16344392519066E-08"
        rpy="0 0 0" />
      <mass
        value="7.14380964147276E-06" />
      <inertia
        ixx="7.09547840102882E-12"
        ixy="-7.27330777191341E-17"
        ixz="-4.28536440227158E-17"
        iyy="1.39367891333543E-11"
        iyz="1.14893231592022E-16"
        izz="8.71236658742557E-12" />
    </inertial>
    <visual>
      <origin
        xyz="0 0 0"
        rpy="0 0 0" />
      <geometry>
        <mesh
          filename="package://cylinder_joint_25asm_13/meshes/link11.STL" />
      </geometry>
      <material
        name="">
        <color
          rgba="0.647058823529412 0.619607843137255 0.588235294117647 1" />
      </material>
    </visual>
    <collision>
      <origin
        xyz="0 0 0"
        rpy="0 0 0" />
      <geometry>
        <mesh
          filename="package://cylinder_joint_25asm_13/meshes/link11.STL" />
      </geometry>
    </collision>
  </link>
  <joint
    name="joint11"
    type="continuous">
    <origin
      xyz="0 0.001 0"
      rpy="3.1416 -1.5708 0" />
    <parent
      link="link10" />
    <child
      link="link11" />
    <axis
      xyz="0 0 1" />
    <limit
      lower="-0.157"
      upper="0.157"
      effort="100"
      velocity="1" />
  </joint>
  <link
    name="link12">
    <inertial>
      <origin
        xyz="-2.21907652592679E-08 0.000838247791607802 1.16344392489562E-08"
        rpy="0 0 0" />
      <mass
        value="7.14380964147276E-06" />
      <inertia
        ixx="7.09547840102882E-12"
        ixy="7.27330777187626E-17"
        ixz="-4.28536440224688E-17"
        iyy="1.39367891333543E-11"
        iyz="-1.14893231591499E-16"
        izz="8.71236658742557E-12" />
    </inertial>
    <visual>
      <origin
        xyz="0 0 0"
        rpy="0 0 0" />
      <geometry>
        <mesh
          filename="package://cylinder_joint_25asm_13/meshes/link12.STL" />
      </geometry>
      <material
        name="">
        <color
          rgba="0.647058823529412 0.619607843137255 0.588235294117647 1" />
      </material>
    </visual>
    <collision>
      <origin
        xyz="0 0 0"
        rpy="0 0 0" />
      <geometry>
        <mesh
          filename="package://cylinder_joint_25asm_13/meshes/link12.STL" />
      </geometry>
    </collision>
  </link>
  <joint
    name="joint12"
    type="continuous">
    <origin
      xyz="0 0.001 0"
      rpy="0 1.5708 0" />
    <parent
      link="link11" />
    <child
      link="link12" />
    <axis
      xyz="0 0 1" />
    <limit
      lower="-0.157"
      upper="0.157"
      effort="100"
      velocity="1" />
  </joint>
  <link
    name="link13">
    <inertial>
      <origin
        xyz="-2.21907652597332E-08 0.000838247791607802 1.1634439250776E-08"
        rpy="0 0 0" />
      <mass
        value="7.14380964147275E-06" />
      <inertia
        ixx="7.09547840102882E-12"
        ixy="7.273307771878E-17"
        ixz="-4.28536440218357E-17"
        iyy="1.39367891333543E-11"
        iyz="-1.14893231593439E-16"
        izz="8.71236658742557E-12" />
    </inertial>
    <visual>
      <origin
        xyz="0 0 0"
        rpy="0 0 0" />
      <geometry>
        <mesh
          filename="package://cylinder_joint_25asm_13/meshes/link13.STL" />
      </geometry>
      <material
        name="">
        <color
          rgba="0.647058823529412 0.619607843137255 0.588235294117647 1" />
      </material>
    </visual>
    <collision>
      <origin
        xyz="0 0 0"
        rpy="0 0 0" />
      <geometry>
        <mesh
          filename="package://cylinder_joint_25asm_13/meshes/link13.STL" />
      </geometry>
    </collision>
  </link>
  <joint
    name="joint13"
    type="continuous">
    <origin
      xyz="0 0.001 0"
      rpy="3.1416 -1.5708 0" />
    <parent
      link="link12" />
    <child
      link="link13" />
    <axis
      xyz="0 0 1" />
    <limit
      lower="-0.157"
      upper="0.157"
      effort="100"
      velocity="1" />
  </joint>
  <link
    name="link14">
    <inertial>
      <origin
        xyz="2.2191E-08 0.00083825 -1.1634E-08"
        rpy="0 0 0" />
      <mass
        value="7.1438E-06" />
      <inertia
        ixx="7.0955E-12"
        ixy="-7.2733E-17"
        ixz="-4.2854E-17"
        iyy="1.3937E-11"
        iyz="1.1489E-16"
        izz="8.7124E-12" />
    </inertial>
    <visual>
      <origin
        xyz="0 0 0"
        rpy="0 0 0" />
      <geometry>
        <mesh
          filename="package://cylinder_joint_25asm_13/meshes/link14.STL" />
      </geometry>
      <material
        name="">
        <color
          rgba="0.64706 0.61961 0.58824 1" />
      </material>
    </visual>
    <collision>
      <origin
        xyz="0 0 0"
        rpy="0 0 0" />
      <geometry>
        <mesh
          filename="package://cylinder_joint_25asm_13/meshes/link14.STL" />
      </geometry>
    </collision>
  </link>
  <joint
    name="joint14"
    type="continuous">
    <origin
      xyz="0 0.001 0"
      rpy="0 1.5708 0" />
    <parent
      link="link13" />
    <child
      link="link14" />
    <axis
      xyz="0 0 1" />
    <limit
      lower="-0.157"
      upper="0.157"
      effort="100"
      velocity="1" />
  </joint>
  <link
    name="link15">
    <inertial>
      <origin
        xyz="2.21907652597663E-08 0.000838247791607804 -1.16344392519056E-08"
        rpy="0 0 0" />
      <mass
        value="7.14380964147278E-06" />
      <inertia
        ixx="7.09547840102885E-12"
        ixy="-7.27330777185466E-17"
        ixz="-4.28536440226031E-17"
        iyy="1.39367891333544E-11"
        iyz="1.14893231592994E-16"
        izz="8.7123665874256E-12" />
    </inertial>
    <visual>
      <origin
        xyz="0 0 0"
        rpy="0 0 0" />
      <geometry>
        <mesh
          filename="package://cylinder_joint_25asm_13/meshes/link15.STL" />
      </geometry>
      <material
        name="">
        <color
          rgba="0.647058823529412 0.619607843137255 0.588235294117647 1" />
      </material>
    </visual>
    <collision>
      <origin
        xyz="0 0 0"
        rpy="0 0 0" />
      <geometry>
        <mesh
          filename="package://cylinder_joint_25asm_13/meshes/link15.STL" />
      </geometry>
    </collision>
  </link>
  <joint
    name="joint15"
    type="continuous">
    <origin
      xyz="0 0.001 0"
      rpy="3.1416 -1.5708 0" />
    <parent
      link="link14" />
    <child
      link="link15" />
    <axis
      xyz="0 0 1" />
    <limit
      lower="-0.157"
      upper="0.157"
      effort="100"
      velocity="1" />
  </joint>
  <link
    name="link16">
    <inertial>
      <origin
        xyz="2.21907652598975E-08 0.000838247791607804 -1.16344392530575E-08"
        rpy="0 0 0" />
      <mass
        value="7.14380964147276E-06" />
      <inertia
        ixx="7.09547840102883E-12"
        ixy="-7.27330777199695E-17"
        ixz="-4.28536440231096E-17"
        iyy="1.39367891333543E-11"
        iyz="1.1489323159145E-16"
        izz="8.71236658742558E-12" />
    </inertial>
    <visual>
      <origin
        xyz="0 0 0"
        rpy="0 0 0" />
      <geometry>
        <mesh
          filename="package://cylinder_joint_25asm_13/meshes/link16.STL" />
      </geometry>
      <material
        name="">
        <color
          rgba="0.647058823529412 0.619607843137255 0.588235294117647 1" />
      </material>
    </visual>
    <collision>
      <origin
        xyz="0 0 0"
        rpy="0 0 0" />
      <geometry>
        <mesh
          filename="package://cylinder_joint_25asm_13/meshes/link16.STL" />
      </geometry>
    </collision>
  </link>
  <joint
    name="joint16"
    type="continuous">
    <origin
      xyz="0 0.001 0"
      rpy="0 1.5708 0" />
    <parent
      link="link15" />
    <child
      link="link16" />
    <axis
      xyz="0 0 1" />
    <limit
      lower="-0.157"
      upper="0.157"
      effort="100"
      velocity="1" />
  </joint>
  <link
    name="link17">
    <inertial>
      <origin
        xyz="2.21907652598001E-08 0.000838247791607804 -1.16344392511635E-08"
        rpy="0 0 0" />
      <mass
        value="7.14380964147277E-06" />
      <inertia
        ixx="7.09547840102883E-12"
        ixy="-7.27330777198489E-17"
        ixz="-4.28536440229726E-17"
        iyy="1.39367891333543E-11"
        iyz="1.14893231590642E-16"
        izz="8.71236658742558E-12" />
    </inertial>
    <visual>
      <origin
        xyz="0 0 0"
        rpy="0 0 0" />
      <geometry>
        <mesh
          filename="package://cylinder_joint_25asm_13/meshes/link17.STL" />
      </geometry>
      <material
        name="">
        <color
          rgba="0.647058823529412 0.619607843137255 0.588235294117647 1" />
      </material>
    </visual>
    <collision>
      <origin
        xyz="0 0 0"
        rpy="0 0 0" />
      <geometry>
        <mesh
          filename="package://cylinder_joint_25asm_13/meshes/link17.STL" />
      </geometry>
    </collision>
  </link>
  <joint
    name="joint17"
    type="continuous">
    <origin
      xyz="0 0.001 0"
      rpy="3.1416 -1.5708 0" />
    <parent
      link="link16" />
    <child
      link="link17" />
    <axis
      xyz="0 0 1" />
    <limit
      lower="-0.157"
      upper="0.157"
      effort="100"
      velocity="1" />
  </joint>
  <link
    name="link18">
    <inertial>
      <origin
        xyz="-2.219076525961E-08 0.000838247791607804 1.16344392482882E-08"
        rpy="0 0 0" />
      <mass
        value="7.14380964147276E-06" />
      <inertia
        ixx="7.09547840102882E-12"
        ixy="7.27330777183652E-17"
        ixz="-4.28536440234473E-17"
        iyy="1.39367891333543E-11"
        iyz="-1.14893231590144E-16"
        izz="8.71236658742557E-12" />
    </inertial>
    <visual>
      <origin
        xyz="0 0 0"
        rpy="0 0 0" />
      <geometry>
        <mesh
          filename="package://cylinder_joint_25asm_13/meshes/link18.STL" />
      </geometry>
      <material
        name="">
        <color
          rgba="0.647058823529412 0.619607843137255 0.588235294117647 1" />
      </material>
    </visual>
    <collision>
      <origin
        xyz="0 0 0"
        rpy="0 0 0" />
      <geometry>
        <mesh
          filename="package://cylinder_joint_25asm_13/meshes/link18.STL" />
      </geometry>
    </collision>
  </link>
  <joint
    name="joint18"
    type="continuous">
    <origin
      xyz="0 0.001 0"
      rpy="0 1.5708 0" />
    <parent
      link="link17" />
    <child
      link="link18" />
    <axis
      xyz="0 0 1" />
    <limit
      lower="-0.157"
      upper="0.157"
      effort="100"
      velocity="1" />
  </joint>
  <link
    name="link19">
    <inertial>
      <origin
        xyz="-2.21907652598299E-08 0.000838247791607804 1.16344392510687E-08"
        rpy="0 0 0" />
      <mass
        value="7.14380964147276E-06" />
      <inertia
        ixx="7.09547840102882E-12"
        ixy="7.27330777192169E-17"
        ixz="-4.28536440226449E-17"
        iyy="1.39367891333543E-11"
        iyz="-1.14893231592272E-16"
        izz="8.71236658742557E-12" />
    </inertial>
    <visual>
      <origin
        xyz="0 0 0"
        rpy="0 0 0" />
      <geometry>
        <mesh
          filename="package://cylinder_joint_25asm_13/meshes/link19.STL" />
      </geometry>
      <material
        name="">
        <color
          rgba="0.647058823529412 0.619607843137255 0.588235294117647 1" />
      </material>
    </visual>
    <collision>
      <origin
        xyz="0 0 0"
        rpy="0 0 0" />
      <geometry>
        <mesh
          filename="package://cylinder_joint_25asm_13/meshes/link19.STL" />
      </geometry>
    </collision>
  </link>
  <joint
    name="joint19"
    type="continuous">
    <origin
      xyz="0 0.001 0"
      rpy="3.1416 -1.5708 0" />
    <parent
      link="link18" />
    <child
      link="link19" />
    <axis
      xyz="0 0 1" />
    <limit
      lower="-0.157"
      upper="0.157"
      effort="100"
      velocity="1" />
  </joint>
  <link
    name="link20">
    <inertial>
      <origin
        xyz="2.21907652598071E-08 0.000838247791607804 -1.16344392541638E-08"
        rpy="0 0 0" />
      <mass
        value="7.14380964147276E-06" />
      <inertia
        ixx="7.09547840102882E-12"
        ixy="-7.27330777195759E-17"
        ixz="-4.28536440210982E-17"
        iyy="1.39367891333543E-11"
        iyz="1.1489323159337E-16"
        izz="8.71236658742558E-12" />
    </inertial>
    <visual>
      <origin
        xyz="0 0 0"
        rpy="0 0 0" />
      <geometry>
        <mesh
          filename="package://cylinder_joint_25asm_13/meshes/link20.STL" />
      </geometry>
      <material
        name="">
        <color
          rgba="0.647058823529412 0.619607843137255 0.588235294117647 1" />
      </material>
    </visual>
    <collision>
      <origin
        xyz="0 0 0"
        rpy="0 0 0" />
      <geometry>
        <mesh
          filename="package://cylinder_joint_25asm_13/meshes/link20.STL" />
      </geometry>
    </collision>
  </link>
  <joint
    name="joint20"
    type="continuous">
    <origin
      xyz="0 0.001 0"
      rpy="0 1.5708 0" />
    <parent
      link="link19" />
    <child
      link="link20" />
    <axis
      xyz="0 0 1" />
    <limit
      lower="-0.157"
      upper="0.157"
      effort="100"
      velocity="1" />
  </joint>
  <link
    name="link21">
    <inertial>
      <origin
        xyz="2.21907652594562E-08 0.000838247791607804 -1.16344392513485E-08"
        rpy="0 0 0" />
      <mass
        value="7.14380964147276E-06" />
      <inertia
        ixx="7.09547840102882E-12"
        ixy="-7.27330777177214E-17"
        ixz="-4.28536440225769E-17"
        iyy="1.39367891333543E-11"
        iyz="1.14893231592281E-16"
        izz="8.71236658742558E-12" />
    </inertial>
    <visual>
      <origin
        xyz="0 0 0"
        rpy="0 0 0" />
      <geometry>
        <mesh
          filename="package://cylinder_joint_25asm_13/meshes/link21.STL" />
      </geometry>
      <material
        name="">
        <color
          rgba="0.647058823529412 0.619607843137255 0.588235294117647 1" />
      </material>
    </visual>
    <collision>
      <origin
        xyz="0 0 0"
        rpy="0 0 0" />
      <geometry>
        <mesh
          filename="package://cylinder_joint_25asm_13/meshes/link21.STL" />
      </geometry>
    </collision>
  </link>
  <joint
    name="joint21"
    type="continuous">
    <origin
      xyz="0 0.001 0"
      rpy="3.1416 -1.5708 0" />
    <parent
      link="link20" />
    <child
      link="link21" />
    <axis
      xyz="0 0 1" />
    <limit
      lower="-0.157"
      upper="0.157"
      effort="100"
      velocity="1" />
  </joint>
  <link
    name="link22">
    <inertial>
      <origin
        xyz="-2.21907652600381E-08 0.0008382477916078 1.16344392488871E-08"
        rpy="0 0 0" />
      <mass
        value="7.14380964147277E-06" />
      <inertia
        ixx="7.09547840102883E-12"
        ixy="7.27330777203359E-17"
        ixz="-4.28536440218424E-17"
        iyy="1.39367891333543E-11"
        iyz="-1.14893231592544E-16"
        izz="8.71236658742558E-12" />
    </inertial>
    <visual>
      <origin
        xyz="0 0 0"
        rpy="0 0 0" />
      <geometry>
        <mesh
          filename="package://cylinder_joint_25asm_13/meshes/link22.STL" />
      </geometry>
      <material
        name="">
        <color
          rgba="0.647058823529412 0.619607843137255 0.588235294117647 1" />
      </material>
    </visual>
    <collision>
      <origin
        xyz="0 0 0"
        rpy="0 0 0" />
      <geometry>
        <mesh
          filename="package://cylinder_joint_25asm_13/meshes/link22.STL" />
      </geometry>
    </collision>
  </link>
  <joint
    name="joint22"
    type="continuous">
    <origin
      xyz="0 0.001 0"
      rpy="0 1.5708 0" />
    <parent
      link="link21" />
    <child
      link="link22" />
    <axis
      xyz="0 0 1" />
    <limit
      lower="-0.157"
      upper="0.157"
      effort="100"
      velocity="1" />
  </joint>
  <link
    name="link23">
    <inertial>
      <origin
        xyz="-2.21907652595946E-08 0.000838247791607804 1.16344392509173E-08"
        rpy="0 0 0" />
      <mass
        value="7.14380964147276E-06" />
      <inertia
        ixx="7.09547840102882E-12"
        ixy="7.27330777196098E-17"
        ixz="-4.28536440222124E-17"
        iyy="1.39367891333543E-11"
        iyz="-1.14893231591804E-16"
        izz="8.71236658742558E-12" />
    </inertial>
    <visual>
      <origin
        xyz="0 0 0"
        rpy="0 0 0" />
      <geometry>
        <mesh
          filename="package://cylinder_joint_25asm_13/meshes/link23.STL" />
      </geometry>
      <material
        name="">
        <color
          rgba="0.647058823529412 0.619607843137255 0.588235294117647 1" />
      </material>
    </visual>
    <collision>
      <origin
        xyz="0 0 0"
        rpy="0 0 0" />
      <geometry>
        <mesh
          filename="package://cylinder_joint_25asm_13/meshes/link23.STL" />
      </geometry>
    </collision>
  </link>
  <joint
    name="joint23"
    type="continuous">
    <origin
      xyz="0 0.001 0"
      rpy="3.1416 -1.5708 0" />
    <parent
      link="link22" />
    <child
      link="link23" />
    <axis
      xyz="0 0 1" />
    <limit
      lower="-0.157"
      upper="0.157"
      effort="100"
      velocity="1" />
  </joint>
  <link
    name="link24">
    <inertial>
      <origin
        xyz="2.21907652598333E-08 0.000838247791607807 -1.16344392545944E-08"
        rpy="0 0 0" />
      <mass
        value="7.14380964147276E-06" />
      <inertia
        ixx="7.09547840102883E-12"
        ixy="-7.27330777197301E-17"
        ixz="-4.28536440214416E-17"
        iyy="1.39367891333543E-11"
        iyz="1.14893231592713E-16"
        izz="8.71236658742557E-12" />
    </inertial>
    <visual>
      <origin
        xyz="0 0 0"
        rpy="0 0 0" />
      <geometry>
        <mesh
          filename="package://cylinder_joint_25asm_13/meshes/link24.STL" />
      </geometry>
      <material
        name="">
        <color
          rgba="0.647058823529412 0.619607843137255 0.588235294117647 1" />
      </material>
    </visual>
    <collision>
      <origin
        xyz="0 0 0"
        rpy="0 0 0" />
      <geometry>
        <mesh
          filename="package://cylinder_joint_25asm_13/meshes/link24.STL" />
      </geometry>
    </collision>
  </link>
  <joint
    name="joint24"
    type="continuous">
    <origin
      xyz="0 0.001 0"
      rpy="0 1.5708 0" />
    <parent
      link="link23" />
    <child
      link="link24" />
    <axis
      xyz="0 0 1" />
    <limit
      lower="-0.157"
      upper="0.157"
      effort="100"
      velocity="1" />
  </joint>
  <link
    name="link25">
    <inertial>
      <origin
        xyz="-1.16344392516958E-08 -0.000161752208392194 -2.21907652602083E-08"
        rpy="0 0 0" />
      <mass
        value="7.14380964147276E-06" />
      <inertia
        ixx="8.71236658742558E-12"
        ixy="1.14893231592732E-16"
        ixz="4.28536440214416E-17"
        iyy="1.39367891333543E-11"
        iyz="7.27330777196951E-17"
        izz="7.09547840102883E-12" />
    </inertial>
    <visual>
      <origin
        xyz="0 0 0"
        rpy="0 0 0" />
      <geometry>
        <mesh
          filename="package://cylinder_joint_25asm_13/meshes/link25.STL" />
      </geometry>
      <material
        name="">
        <color
          rgba="0.647058823529412 0.619607843137255 0.588235294117647 1" />
      </material>
    </visual>
    <collision>
      <origin
        xyz="0 0 0"
        rpy="0 0 0" />
      <geometry>
        <mesh
          filename="package://cylinder_joint_25asm_13/meshes/link25.STL" />
      </geometry>
    </collision>
  </link>
  <joint
    name="joint25"
    type="fixed">
    <origin
      xyz="0 0.001 0"
      rpy="3.1416 -1.5708 0" />
    <parent
      link="link24" />
    <child
      link="link25" />
    <axis
      xyz="0 0 0" />
    <limit
      lower="-0.157"
      upper="0.157"
      effort="100"
      velocity="1" />
  </joint>
</robot>